<?xml version="1.0" ?>
<sdf version="1.10">
   <model name='vehicle_blue' canonical_link='base_link'>
       <link name='base_link'>
           <pose relative_to='__model__'>0.1 0 0.08 0 0 0</pose>
           <inertial>
               <mass>2.0</mass>
               <inertia>
                   <ixx>0.008333</ixx>
                   <ixy>0</ixy>
                   <ixz>0</ixz>
                   <iyy>0.028333</iyy>
                   <iyz>0</iyz>
                   <izz>0.033333</izz>
               </inertia>
           </inertial>
           <visual name='visual'>
               <geometry>
                   <box>
                       <size>0.4 0.2 0.1</size>
                   </box>
               </geometry>
               <material>
                   <ambient>0.0 0.0 1.0 1</ambient>
                   <diffuse>0.0 0.0 1.0 1</diffuse>
                   <specular>0.0 0.0 1.0 1</specular>
               </material>
           </visual>
           <collision name='collision'>
               <geometry>
                   <box>
                       <size>0.4 0.2 0.1</size>
                   </box>
               </geometry>
           </collision>
       </link>
       <link name='left_wheel'>
           <pose relative_to="base_link">-0.1 0.12 0 -1.5707 0 0</pose>
           <inertial>
               <mass>3.0</mass>
               <inertia>
                   <ixx>0.0052</ixx>
                   <ixy>0</ixy>
                   <ixz>0</ixz>
                   <iyy>0.0052</iyy>
                   <iyz>0</iyz>
                   <izz>0.0096</izz>
               </inertia>
           </inertial>
           <visual name='visual'>
               <geometry>
                   <cylinder>
                       <radius>0.08</radius>
                       <length>0.04</length>
                   </cylinder>
               </geometry>
               <material>
                   <ambient>1.0 0.0 0.0 1</ambient>
                   <diffuse>1.0 0.0 0.0 1</diffuse>
                   <specular>1.0 0.0 0.0 1</specular>
               </material>
           </visual>
           <collision name='collision'>
               <geometry>
                   <cylinder>
                       <radius>0.08</radius>
                       <length>0.04</length>
                   </cylinder>
               </geometry>
               <surface>
                   <friction>
                       <ode>
                           <mu>1.0</mu>
                           <mu2>1.0</mu2>
                           <slip1>0.0</slip1>
                           <slip2>0.0</slip2>
                       </ode>
                   </friction>
               </surface>
           </collision>
       </link>
       <link name='right_wheel'>
           <pose relative_to="base_link">-0.1 -0.12 0 -1.5707 0 0</pose>
           <inertial>
               <mass>3.0</mass>
               <inertia>
                   <ixx>0.0052</ixx>
                   <ixy>0</ixy>
                   <ixz>0</ixz>
                   <iyy>0.0052</iyy>
                   <iyz>0</iyz>
                   <izz>0.0096</izz>
               </inertia>
           </inertial>
           <visual name='visual'>
               <geometry>
                   <cylinder>
                       <radius>0.08</radius>
                       <length>0.04</length>
                   </cylinder>
               </geometry>
               <material>
                   <ambient>1.0 0.0 0.0 1</ambient>
                   <diffuse>1.0 0.0 0.0 1</diffuse>
                   <specular>1.0 0.0 0.0 1</specular>
               </material>
           </visual>
           <collision name='collision'>
               <geometry>
                   <cylinder>
                       <radius>0.08</radius>
                       <length>0.04</length>
                   </cylinder>
               </geometry>
               <surface>
                   <friction>
                       <ode>
                           <mu>1.0</mu>
                           <mu2>1.0</mu2>
                           <slip1>0.0</slip1>
                           <slip2>0.0</slip2>
                       </ode>
                   </friction>
               </surface>
           </collision>
       </link>
       <frame name="caster_frame" attached_to='base_link'>
           <pose>0.8 0 -0.2 0 0 0</pose>
       </frame>
       <link name='caster'>
           <pose relative_to='base_link'>0.1 0 -0.08 0 0 0</pose>
           <inertial>
               <mass>0.5</mass>
               <inertia>
                   <ixx>0.00008</ixx>
                   <ixy>0</ixy>
                   <ixz>0</ixz>
                   <iyy>0.00008</iyy>
                   <iyz>0</iyz>
                   <izz>0.00008</izz>
               </inertia>
           </inertial>
           <visual name='visual'>
               <geometry>
                   <sphere>
                       <radius>0.04</radius>
                   </sphere>
               </geometry>
               <material>
                   <ambient>0.0 1 0.0 1</ambient>
                   <diffuse>0.0 1 0.0 1</diffuse>
                   <specular>0.0 1 0.0 1</specular>
               </material>
           </visual>
           <collision name='collision'>
               <geometry>
                   <sphere>
                       <radius>0.04</radius>
                   </sphere>
               </geometry>
               <surface>
                   <friction>
                       <ode>
                           <mu>0.001</mu>
                           <mu2>0.001</mu2>
                           <slip1>1.0</slip1>
                           <slip2>1.0</slip2>
                       </ode>
                   </friction>
               </surface>
           </collision>
       </link>
       
       <link name='lidar'>
           <pose relative_to="base_link">0.16 0 0.08 0 0 0</pose>
           <inertial>
               <mass>0.1</mass>
               <inertia>
                   <ixx>0.0000027</ixx>
                   <ixy>0</ixy>
                   <ixz>0</ixz>
                   <iyy>0.0000027</iyy>
                   <iyz>0</iyz>
                   <izz>0.0000027</izz>
               </inertia>
           </inertial>
           <visual name='visual'>
               <geometry>
                   <cylinder>
                       <radius>0.01</radius>
                       <length>0.04</length>
                   </cylinder>
               </geometry>
               <material>
                   <ambient>1.0 1.0 0.0 1</ambient>
                   <diffuse>1.0 1.0 0.0 1</diffuse>
                   <specular>1.0 1.0 0.0 1</specular>
               </material>
           </visual>
           <collision name='collision'>
               <geometry>
                   <cylinder>
                       <radius>0.01</radius>
                       <length>0.04</length>
                   </cylinder>
               </geometry>
           </collision>
           <sensor name='lidar_sensor' type='gpu_lidar'>
               <pose>0 0 0 0 0 0</pose>
               <topic>/lidar</topic>
               <update_rate>10</update_rate>
               <frame_id>vehicle_blue/lidar</frame_id>
               <lidar>
                   <scan>
                       <horizontal>
                           <samples>36</samples>
                           <resolution>1</resolution>
                           <min_angle>-3.14159</min_angle>
                           <max_angle>3.14159</max_angle>
                       </horizontal>
                   </scan>
                   <range>
                       <min>0.1</min>
                       <max>30.0</max>
                       <resolution>0.01</resolution>
                   </range>
                   <noise>
                       <type>gaussian</type>
                       <mean>0.0</mean>
                       <stddev>0.01</stddev>
                   </noise>
               </lidar>
               <always_on>1</always_on>
               <visualize>true</visualize>
           </sensor>
       </link>
       <joint name='left_wheel_joint' type='revolute'>
           <pose relative_to='left_wheel'/>
           <parent>base_link</parent>
           <child>left_wheel</child>
           <axis>
               <xyz expressed_in='__model__'>0 1 0</xyz>
               <limit>
                   <lower>-1.79769e+308</lower>
                   <upper>1.79769e+308</upper>
               </limit>
           </axis>
       </joint>
       <joint name='right_wheel_joint' type='revolute'>
           <pose relative_to='right_wheel'/>
           <parent>base_link</parent>
           <child>right_wheel</child>
           <axis>
               <xyz expressed_in='__model__'>0 1 0</xyz>
               <limit>
                   <lower>-1.79769e+308</lower>
                   <upper>1.79769e+308</upper>
               </limit>
           </axis>
       </joint>
       <joint name='caster_wheel' type='ball'>
           <parent>base_link</parent>
           <child>caster</child>
       </joint>
       
       <joint name='lidar_joint' type='fixed'>
           <parent>base_link</parent>
           <child>lidar</child>
       </joint>

              <!-- Plugins inside the model -->
       <plugin filename="gz-sim-diff-drive-system" name="gz::sim::systems::DiffDrive">
           <left_joint>left_wheel_joint</left_joint>
           <right_joint>right_wheel_joint</right_joint>
           <wheel_separation>0.24</wheel_separation>
           <wheel_radius>0.08</wheel_radius>
           <odom_publish_frequency>30</odom_publish_frequency>
           <max_wheel_torque>12.0</max_wheel_torque>
           <max_wheel_acceleration>6.0</max_wheel_acceleration>
           <topic>/cmd_vel</topic>
           <odom_topic>/odom</odom_topic>
           <frame_id>odom</frame_id>
           <child_frame_id>base_link</child_frame_id>
           <tf_topic>/tf</tf_topic>
           <publish_odom_tf>true</publish_odom_tf>

       </plugin>

       <plugin filename="gz-sim-joint-state-publisher-system" name="gz::sim::systems::JointStatePublisher">
           <topic>/joint_states</topic>
       </plugin>

       <plugin filename="gz-sim-pose-publisher-system" name="gz::sim::systems::PosePublisher">
           <publish_link_pose>true</publish_link_pose>
           <publish_sensor_pose>false</publish_sensor_pose>
           <publish_collision_pose>false</publish_collision_pose>
           <publish_visual_pose>false</publish_visual_pose>
           <publish_nested_model_pose>true</publish_nested_model_pose>
           <use_pose_vector_msg>true</use_pose_vector_msg>
           <static_publisher>false</static_publisher>
           <update_frequency>30</update_frequency>
           <topic>/model/vehicle_blue/pose</topic>
       </plugin>
       
       <plugin filename="gz-sim-sensors-system" name="gz::sim::systems::Sensors">
           <render_engine>ogre2</render_engine>
       </plugin>
   </model>
</sdf>
